Workbook

Sheet Computations
A1: Coefficients for physical constants (at STP)
B2: Phase: | C2: a-quartz | D2: b-quartz | E2: orthoclase | F2: albite | G2: anorthite | H2: muscovite | I2: phlogopite | J2: annite | K2: hornblende | L2: diopside | M2: hedenbergite | N2: enstatite | O2: ferrosilite | P2: forsterite | Q2: fayalite | R2: spinel | S2: pyrope | T2: almandine
A3: molecular unit | C3: SiO2 | D3: SiO2 | E3: KAlSi3O8 | F3: NaAlSi3O8 | G3: CaAlSi2O8 | H3: KAl3Si3O10(OH)2 | I3: KMg3AlSi3O10(F,OH)2 | J3: KFe3AlSi3O10(F,OH)2 | K3: Ca2(Mg,Fe,Al)5(Al,Si)8O22(OH)2 | L3: CaMgSi2O6 | M3: CaFeSi2O6 | N3: MgSiO3 | O3: FeSiO3 | P3: Mg2SiO4 | Q3: Fe2SiO4 | R3: MgAl2O4 | S3: Mg3Al2Si3O12 | T3: Fe3Al2Si3O12
A4: gram formula weight (g/mol) | B4: m0 | C4: 60.085 | D4: 60.085 | E4: 278.33 | F4: 262.23 | G4: 278.169 | H4: 398.248 | I4: 417.24 | J4: 511.866 | K4: 864.72 | L4: 216.56 | M4: 248.09 | N4: 200.79 | O4: 263.86 | P4: 140.7 | Q4: 203.77 | R4: 142.27 | S4: 403.09 | T4: 497.7
A5: molar volume (cm3/mol) | B5: V0 | C5: 22.7 | D5: 23.7 | E5: 108.9 | F5: 100.1 | G5: 100.8 | H5: 140.8 | I5: 149.7 | J5: 154.3 | K5: 266.2 | L5: 66.2 | M5: 68 | N5: 62.6 | O5: 65.9 | P5: 43.7 | Q5: 46.3 | R5: 39.8 | S5: 113.1 | T5: 115.1
A6: density @298K (kg/m3) | B6: r298 | C6: 2648 | D6: 2530 | E6: 2555 | F6: 2620 | G6: 2760 | H6: 2828 | I6: 2788 | J6: 3317 | K6: 3248 | L6: 3272 | M6: 3651 | N6: 3206 | O6: 4003 | P6: 3222 | Q6: 4400 | R6: 3575 | S6: 3565 | T6: 4324
A7: wt% H2O | C7: 0 | D7: 0 | E7: 0 | F7: 0 | G7: 0 | H7: 4.5 | I7: 4.5 | J7: 3.5 | K7: 2.5 | L7: 0 | M7: 0 | N7: 0 | O7: 0 | P7: 0 | Q7: 0 | R7: 0 | S7: 0 | T7: 0
A8: expansivity aV = a0 + a1T + a2T-2 (/K) | B8: a0 x 105 | C8: 1.417 | D8: -0.44 | E8: 3.4 | F8: 1.9801 | G8: 1.2491 | H8: 3.537 | I8: 5.8 | J8: 3.7 | K8: 2.075 | L8: 3.33 | M8: 2.98 | N8: 2.972 | O8: 2.875 | P8: 2.854 | Q8: 2.386 | R8: 1.96 | S8: 2.311 | T8: 1.776
B9: a1 x 108 | C9: 9.6581 | D9: 0 | E9: 0 | F9: 1.0065 | G9: -0.0162 | H9: 0 | I9: 0 | J9: 0 | K9: 1.027 | L9: 0 | M9: 0 | N9: 0.5711 | O9: 0 | P9: 1.008 | Q9: 1.153 | R9: 1.64 | S9: 0.5956 | T9: 1.214
B10: a2 | C10: -1.6973 | D10: 0 | E10: 0 | F10: -0.976 | G10: 0.0161 | H10: 0 | I10: 0 | J10: 0 | K10: 0 | L10: 0 | M10: 0 | N10: 0 | O10: 0 | P10: -0.3842 | Q10: -0.0518 | R10: 0 | S10: -0.4538 | T10: -0.5071
A11: specific heat capacity Cp = c0 + c1T-0.5 + c2T-2 + c3T-3 (kJ/kg-K) | B11: c0 | C11: 1.7699 | D11: 0.9647 | E11: 1.4445 | F11: 1.5012 | G11: 1.5793 | H11: 1.668 | I11: 1.4354 | J11: 1.2777 | K11: 1.6559 | L11: 1.4103 | M11: 1.3712 | N11: 1.6592 | O11: 1.3204 | P11: 1.6572 | Q11: 1.2366 | R11: 1.7197 | S11: 1.4657 | T11: 1.2485
B12: c1 | C12: -23.49 | D12: -0.0004 | E12: -9.5303 | F12: -9.2116 | G12: -4.7252 | H12: -10.994 | I12: -4.0508 | J12: -5.661 | K12: -13.126 | L12: -7.4109 | M12: -10.668 | N12: -11.959 | O12: -10.559 | P12: -12.804 | Q12: -9.882 | R12: -14.086 | S12: -7.012 | T12: -6.605
B13: c2 | C13: 45.947 | D13: 30.546 | E13: -26.395 | F13: -30.099 | G13: 0 | H13: -36.79 | I13: -61.28 | J13: -42.813 | K13: 1.5163 | L13: -33.09 | M13: -32.729 | N13: -22.616 | O13: -3.444 | P13: 0 | Q13: 0 | R13: 0 | S13: -33.042 | T13: -30.298
B14: c3 | C14: -7.2006 | D14: -0.0018 | E14: 3.6781 | F14: 4.0829 | G14: -1.1395 | H14: 5.0614 | I14: 8.995 | J14: 6.9201 | K14: -2.6059 | L14: 4.2567 | M14: -0.0042 | N14: 2.7805 | O14: -0.2858 | P14: -1.9042 | Q14: -0.3052 | R14: 0 | S14: 3.1262 | T14: 4.4437
A15: isothermal bulk modulus (GPa) | B15: KT | C15: 37.12 | D15: 57.01 | E15: 58.3 | F15: 57.76 | G15: 81.86 | H15: 49 | I15: 49.7 | J15: 49.7 | K15: 93.97 | L15: 113 | M15: 119.2 | N15: 105.8 | O15: 100.17 | P15: 127.3 | Q15: 136.7 | R15: 196.2 | S15: 173.81 | T15: 174.1
A16: dKT/dP | B16: KT' | C16: 5.99 | D16: 4 | E16: 4 | F16: 4 | G16: 4 | H16: 4 | I16: 8.59 | J16: =I16 -> 8.59 | K16: 4 | L16: 4.8 | M16: 4 | N16: 8.5 | O16: 4 | P16: 5.37 | Q16: 5.16 | R16: 4 | S16: 5 | T16: 6
A17: shear modulus (GPa) | B17: m | C17: 44.8 | D17: 41.4 | E17: 28.1 | F17: 29.7825 | G17: 36.04844 | H17: 29.54 | I17: 22.94 | J17: 22.94 | K17: 54.5 | L17: 64.9 | M17: 61 | N17: 76.8 | O17: 52 | P17: 81.6 | Q17: 51 | R17: 107.81 | S17: 94 | T17: 92.1
A18: dlnm/ dlnr | B18: G | C18: 40.1 | D18: =D21 -> 4.11 | E18: =E21 -> 4.44 | F18: 13 | G18: 6.8 | H18: 4.5 | I18: =I21 -> 9.14 | J18: =J21 -> 9.14 | K18: =K21 -> 5.1 | L18: =L21 -> 6.04 | M18: =M21 -> 5.21 | N18: =N21 -> 9.39 | O18: =O21 -> 5.05 | P18: 5.19 | Q18: 4.69 | R18: 4.2 | S18: 4.06 | T18: 5.517
A19: dm/dP | B19: m' | C19: 0.46 | D19: =(5*D17)/(3*D15) -> 1.210314 | E19: =(5*E17)/(3*E15) -> 0.80331618 | F19: =D19 -> 1.210314 | G19: 3.48 | H19: 1 | I19: =(5*I17)/(3*I15) -> 0.76928236 | J19: =(5*J17)/(3*J15) -> 0.76928236 | K19: =(5*K17)/(3*K15) -> 0.96662055 | L19: 2 | M19: =(5*M17)/(3*M15) -> 0.85290828 | N19: 2 | O19: 2 | P19: 1.82 | Q19: 0.62 | R19: =(5*R17)/(3*R15) -> 0.91581719 | S19: 1.5 | T19: 1.6
A20: first Grüneisen parameter | B20: gth | C20: 0.666 | D20: 0.11 | E20: 0.44 | F20: 0.57 | G20: 0.47 | H20: 0.52 | I20: 0.55 | J20: 0.55 | K20: 1.1 | L20: 1.24 | M20: 1.21 | N20: 0.89 | O20: 1.05 | P20: 1.16 | Q20: 1.1 | R20: 1.28 | S20: 1.25 | T20: 1.02
A21: second Grüneisen parameter | B21: dT | C21: 8.415 | D21: =D20+D16 -> 4.11 | E21: =E20+E16 -> 4.44 | F21: =F20+F16 -> 4.57 | G21: =G20+G16 -> 4.47 | H21: =H20+H16 -> 4.52 | I21: =I20+I16 -> 9.14 | J21: =J20+J16 -> 9.14 | K21: =K20+K16 -> 5.1 | ... O21: =O20+O16 -> 5.05 | P21: 5.5 | Q21: 5.4 | R21: 6.5 | S21: 5.3 | T21: 5.517 | X21: modal mineral proportions for common rock types
U22: Total | X22: a-quartz | Y22: b-quartz | Z22: orthoclase | AA22: albite | AB22: anorthite | AC22: muscovite | AD22: phlogopite | AE22: annite | AF22: hornblende | AG22: diopside | AH22: hedenbergite | AI22: enstatite | AJ22: ferrosilite | AK22: forsterite | AL22: fayalite | AM22: spinel | AN22: pyrope | AO22: almandine | AP22: total
B23: Modal Volume | C23: 27 | E23: 15 | F23: 32 | G23: 8 | I23: 5 | K23: 13 | U23: =SUM(C23:T23) -> 100 | W23: granite | X23: 27 | Z23: 15 | AA23: 32 | AB23: 8 | AD23: 5 | AF23: 13 | AP23: =SUM(X23:AO23) -> 100
W24: mafic granulite | X24: 2 | Z24: 10 | AA24: 10 | AB24: 18 | AF24: 47 | AG24: 1 | AH24: 1 | AI24: 1 | AJ24: 1 | AO24: 9 | AP24: =SUM(X24:AO24) -> 100
A25: V(P,T) | B25: Volume Fraction (pressure and temperature-dependence | W25: lherzolite | AG25: 5.47 | AH25: 0.53 | AI25: 15.47 | AJ25: 1.53 | AK25: 63.65 | AL25: 3.35 | AN25: 5.58 | AO25: 1.42 | AP25: =SUM(X25:AO25) -> 97
A26: Pressure (MPa) | B26: Temperature (K) | C26: a-quartz | D26: b-quartz | E26: orthoclase | F26: albite | G26: anorthite | H26: muscovite | I26: phlogopite | J26: annite | K26: hornblende | L26: diopside | M26: hedenbergite | N26: enstatite | O26: ferrosilite | P26: forsterite | Q26: fayalite | R26: spinel | S26: pyrope | T26: almandine | U26: Total
A27: 0.1 | B27: 298 | C27: =IF(C$23=0,0,C$23*C$6/C441) -> #DIV/0! | D27: =IF(D$23=0,0,D$23*D$6/D441) -> 0 | E27: =IF(E$23=0,0,E$23*E$6/E441) -> #DIV/0! | F27: =IF(F$23=0,0,F$23*F$6/F441) -> #DIV/0! | G27: =IF(G$23=0,0,G$23*G$6/G441) -> #DIV/0! | H27: =IF(H$23=0,0,H$23*H$6/H441) -> 0 | I27: =IF(I$23=0,0,I$23*I$6/I441) -> #DIV/0! | J27: =IF(J$23=0,0,J$23*J$6/J441) -> 0 | ... T27: =IF(T$23=0,0,T$23*T$6/T441) -> 0 | U27: =SUM(C27:T27) -> #DIV/0!
A28: 0.1 | B28: =B27+50 -> 348 | C28: =IF(C$23=0,0,C$23*C$6/C442) -> #DIV/0! | D28: =IF(D$23=0,0,D$23*D$6/D442) -> 0 | E28: =IF(E$23=0,0,E$23*E$6/E442) -> #DIV/0! | F28: =IF(F$23=0,0,F$23*F$6/F442) -> #DIV/0! | G28: =IF(G$23=0,0,G$23*G$6/G442) -> #DIV/0! | H28: =IF(H$23=0,0,H$23*H$6/H442) -> 0 | I28: =IF(I$23=0,0,I$23*I$6/I442) -> #DIV/0! | J28: =IF(J$23=0,0,J$23*J$6/J442) -> 0 | ... T28: =IF(T$23=0,0,T$23*T$6/T442) -> 0 | U28: =SUM(C28:T28) -> #DIV/0!
A29: 0.1 | B29: =B28+50 -> 398 | C29: =IF(C$23=0,0,C$23*C$6/C443) -> #DIV/0! | D29: =IF(D$23=0,0,D$23*D$6/D443) -> 0 | E29: =IF(E$23=0,0,E$23*E$6/E443) -> #DIV/0! | F29: =IF(F$23=0,0,F$23*F$6/F443) -> #DIV/0! | G29: =IF(G$23=0,0,G$23*G$6/G443) -> #DIV/0! | H29: =IF(H$23=0,0,H$23*H$6/H443) -> 0 | I29: =IF(I$23=0,0,I$23*I$6/I443) -> #DIV/0! | J29: =IF(J$23=0,0,J$23*J$6/J443) -> 0 | ... T29: =IF(T$23=0,0,T$23*T$6/T443) -> 0 | U29: =SUM(C29:T29) -> #DIV/0!
A30: 0.1 | B30: =B29+50 -> 448 | C30: =IF(C$23=0,0,C$23*C$6/C444) -> #DIV/0! | D30: =IF(D$23=0,0,D$23*D$6/D444) -> 0 | E30: =IF(E$23=0,0,E$23*E$6/E444) -> #DIV/0! | F30: =IF(F$23=0,0,F$23*F$6/F444) -> #DIV/0! | G30: =IF(G$23=0,0,G$23*G$6/G444) -> #DIV/0! | H30: =IF(H$23=0,0,H$23*H$6/H444) -> 0 | I30: =IF(I$23=0,0,I$23*I$6/I444) -> #DIV/0! | J30: =IF(J$23=0,0,J$23*J$6/J444) -> 0 | ... T30: =IF(T$23=0,0,T$23*T$6/T444) -> 0 | U30: =SUM(C30:T30) -> #DIV/0!
A31: 0.1 | B31: =B30+50 -> 498 | C31: =IF(C$23=0,0,C$23*C$6/C445) -> #DIV/0! | D31: =IF(D$23=0,0,D$23*D$6/D445) -> 0 | E31: =IF(E$23=0,0,E$23*E$6/E445) -> #DIV/0! | F31: =IF(F$23=0,0,F$23*F$6/F445) -> #DIV/0! | G31: =IF(G$23=0,0,G$23*G$6/G445) -> #DIV/0! | H31: =IF(H$23=0,0,H$23*H$6/H445) -> 0 | I31: =IF(I$23=0,0,I$23*I$6/I445) -> #DIV/0! | J31: =IF(J$23=0,0,J$23*J$6/J445) -> 0 | ... T31: =IF(T$23=0,0,T$23*T$6/T445) -> 0 | U31: =SUM(C31:T31) -> #DIV/0!
A32: 0.1 | B32: =B31+50 -> 548 | C32: =IF(C$23=0,0,C$23*C$6/C446) -> #DIV/0! | D32: =IF(D$23=0,0,D$23*D$6/D446) -> 0 | E32: =IF(E$23=0,0,E$23*E$6/E446) -> #DIV/0! | F32: =IF(F$23=0,0,F$23*F$6/F446) -> #DIV/0! | G32: =IF(G$23=0,0,G$23*G$6/G446) -> #DIV/0! | H32: =IF(H$23=0,0,H$23*H$6/H446) -> 0 | I32: =IF(I$23=0,0,I$23*I$6/I446) -> #DIV/0! | J32: =IF(J$23=0,0,J$23*J$6/J446) -> 0 | ... T32: =IF(T$23=0,0,T$23*T$6/T446) -> 0 | U32: =SUM(C32:T32) -> #DIV/0!
A33: 0.1 | B33: =B32+50 -> 598 | C33: =IF(C$23=0,0,C$23*C$6/C447) -> #DIV/0! | D33: =IF(D$23=0,0,D$23*D$6/D447) -> 0 | E33: =IF(E$23=0,0,E$23*E$6/E447) -> #DIV/0! | F33: =IF(F$23=0,0,F$23*F$6/F447) -> #DIV/0! | G33: =IF(G$23=0,0,G$23*G$6/G447) -> #DIV/0! | H33: =IF(H$23=0,0,H$23*H$6/H447) -> 0 | I33: =IF(I$23=0,0,I$23*I$6/I447) -> #DIV/0! | J33: =IF(J$23=0,0,J$23*J$6/J447) -> 0 | ... T33: =IF(T$23=0,0,T$23*T$6/T447) -> 0 | U33: =SUM(C33:T33) -> #DIV/0!
A34: 0.1 | B34: =B33+50 -> 648 | C34: =IF(C$23=0,0,C$23*C$6/C448) -> #DIV/0! | D34: =IF(D$23=0,0,D$23*D$6/D448) -> 0 | E34: =IF(E$23=0,0,E$23*E$6/E448) -> #DIV/0! | F34: =IF(F$23=0,0,F$23*F$6/F448) -> #DIV/0! | G34: =IF(G$23=0,0,G$23*G$6/G448) -> #DIV/0! | H34: =IF(H$23=0,0,H$23*H$6/H448) -> 0 | I34: =IF(I$23=0,0,I$23*I$6/I448) -> #DIV/0! | J34: =IF(J$23=0,0,J$23*J$6/J448) -> 0 | ... T34: =IF(T$23=0,0,T$23*T$6/T448) -> 0 | U34: =SUM(C34:T34) -> #DIV/0!
A35: 0.1 | B35: =B34+50 -> 698 | C35: =IF(C$23=0,0,C$23*C$6/C449) -> #DIV/0! | D35: =IF(D$23=0,0,D$23*D$6/D449) -> 0 | E35: =IF(E$23=0,0,E$23*E$6/E449) -> #DIV/0! | F35: =IF(F$23=0,0,F$23*F$6/F449) -> #DIV/0! | G35: =IF(G$23=0,0,G$23*G$6/G449) -> #DIV/0! | H35: =IF(H$23=0,0,H$23*H$6/H449) -> 0 | I35: =IF(I$23=0,0,I$23*I$6/I449) -> #DIV/0! | J35: =IF(J$23=0,0,J$23*J$6/J449) -> 0 | ... T35: =IF(T$23=0,0,T$23*T$6/T449) -> 0 | U35: =SUM(C35:T35) -> #DIV/0!
A36: 0.1 | B36: =B35+50 -> 748 | C36: =IF(C$23=0,0,C$23*C$6/C450) -> #DIV/0! | D36: =IF(D$23=0,0,D$23*D$6/D450) -> 0 | E36: =IF(E$23=0,0,E$23*E$6/E450) -> #DIV/0! | F36: =IF(F$23=0,0,F$23*F$6/F450) -> #DIV/0! | G36: =IF(G$23=0,0,G$23*G$6/G450) -> #DIV/0! | H36: =IF(H$23=0,0,H$23*H$6/H450) -> 0 | I36: =IF(I$23=0,0,I$23*I$6/I450) -> #DIV/0! | J36: =IF(J$23=0,0,J$23*J$6/J450) -> 0 | ... T36: =IF(T$23=0,0,T$23*T$6/T450) -> 0 | U36: =SUM(C36:T36) -> #DIV/0!
A37: 0.1 | B37: =B36+50 -> 798 | C37: =IF(C$23=0,0,C$23*C$6/C451) -> #DIV/0! | D37: =IF(D$23=0,0,D$23*D$6/D451) -> 0 | E37: =IF(E$23=0,0,E$23*E$6/E451) -> #DIV/0! | F37: =IF(F$23=0,0,F$23*F$6/F451) -> #DIV/0! | G37: =IF(G$23=0,0,G$23*G$6/G451) -> #DIV/0! | H37: =IF(H$23=0,0,H$23*H$6/H451) -> 0 | I37: =IF(I$23=0,0,I$23*I$6/I451) -> #DIV/0! | J37: =IF(J$23=0,0,J$23*J$6/J451) -> 0 | ... T37: =IF(T$23=0,0,T$23*T$6/T451) -> 0 | U37: =SUM(C37:T37) -> #DIV/0!
A38: 0.1 | B38: =B37+50 -> 848 | C38: =IF(C$23=0,0,C$23*C$6/C452) -> #DIV/0! | D38: =IF(D$23=0,0,D$23*D$6/D452) -> 0 | E38: =IF(E$23=0,0,E$23*E$6/E452) -> #DIV/0! | F38: =IF(F$23=0,0,F$23*F$6/F452) -> #DIV/0! | G38: =IF(G$23=0,0,G$23*G$6/G452) -> #DIV/0! | H38: =IF(H$23=0,0,H$23*H$6/H452) -> 0 | I38: =IF(I$23=0,0,I$23*I$6/I452) -> #DIV/0! | J38: =IF(J$23=0,0,J$23*J$6/J452) -> 0 | ... T38: =IF(T$23=0,0,T$23*T$6/T452) -> 0 | U38: =SUM(C38:T38) -> #DIV/0!
A39: 0.1 | B39: =B38+50 -> 898 | C39: =IF(C$23=0,0,C$23*C$6/C453) -> #DIV/0! | D39: =IF(D$23=0,0,D$23*D$6/D453) -> 0 | E39: =IF(E$23=0,0,E$23*E$6/E453) -> #DIV/0! | F39: =IF(F$23=0,0,F$23*F$6/F453) -> #DIV/0! | G39: =IF(G$23=0,0,G$23*G$6/G453) -> #DIV/0! | H39: =IF(H$23=0,0,H$23*H$6/H453) -> 0 | I39: =IF(I$23=0,0,I$23*I$6/I453) -> #DIV/0! | J39: =IF(J$23=0,0,J$23*J$6/J453) -> 0 | ... T39: =IF(T$23=0,0,T$23*T$6/T453) -> 0 | U39: =SUM(C39:T39) -> #DIV/0!
A40: 0.1 | B40: =B39+50 -> 948 | C40: =IF(C$23=0,0,C$23*C$6/C454) -> #DIV/0! | D40: =IF(D$23=0,0,D$23*D$6/D454) -> 0 | E40: =IF(E$23=0,0,E$23*E$6/E454) -> #DIV/0! | F40: =IF(F$23=0,0,F$23*F$6/F454) -> #DIV/0! | G40: =IF(G$23=0,0,G$23*G$6/G454) -> #DIV/0! | H40: =IF(H$23=0,0,H$23*H$6/H454) -> 0 | I40: =IF(I$23=0,0,I$23*I$6/I454) -> #DIV/0! | J40: =IF(J$23=0,0,J$23*J$6/J454) -> 0 | ... T40: =IF(T$23=0,0,T$23*T$6/T454) -> 0 | U40: =SUM(C40:T40) -> #DIV/0!
...

Sheet Figures
A1: These cells are automatically filled in from the computations worksheet so long as you do not alter the default locations of computed values. Scroll down to see plots.
A2: Pressure | B2: Temperature | C2: Expansivity | D2: Density | E2: Bulk Modulus (isothermal) | F2: Bulk Modulus (adiabatic) | G2: Shear Modulus | H2: Specific Heat Capacity | I2: P-wave Velocity | J2: S-wave Velocity | K2: Vp/Vs Ratio | L2: Poisson Ratio
A3: Mpa | B3: K | C3: K-1 | D3: kg m-3 | E3: GPa | F3: GPa | G3: GPa | H3: J kg-1 K-1 | I3: km s-1 | J3: km s-1 | K3: - | L3: -
A4: 0.1 | B4: 298 | C4: =Computations!AQ500 -> 0 | D4: =Computations!AQ441 -> #DIV/0! | E4: =Computations!BJ382+Figures!BJ386 -> 0 | F4: =Computations!BJ559 -> 0 | G4: =Computations!BJ677 -> 0 | H4: =Computations!AQ736 -> 0 | I4: =Computations!BJ795 -> 0 | J4: =Computations!BJ854 -> 0 | K4: =I4/J4 -> #DIV/0! | L4: =0.5*(K4^2-2)/(K4^2-1) -> #DIV/0!
A5: 0.1 | B5: =B4+50 -> 348 | C5: =Computations!AQ501 -> 0 | D5: =Computations!AQ442 -> #DIV/0! | E5: =Computations!BJ383+Figures!BJ387 -> 0 | F5: =Computations!BJ560 -> 0 | G5: =Computations!BJ678 -> 0 | H5: =Computations!AQ737 -> 0 | I5: =Computations!BJ796 -> 0 | J5: =Computations!BJ855 -> 0 | K5: =I5/J5 -> #DIV/0! | L5: =0.5*(K5^2-2)/(K5^2-1) -> #DIV/0!
A6: 0.1 | B6: =B5+50 -> 398 | C6: =Computations!AQ502 -> 0 | D6: =Computations!AQ443 -> #DIV/0! | E6: =Computations!BJ384+Figures!BJ388 -> 0 | F6: =Computations!BJ561 -> 0 | G6: =Computations!BJ679 -> 0 | H6: =Computations!AQ738 -> 0 | I6: =Computations!BJ797 -> 0 | J6: =Computations!BJ856 -> 0 | K6: =I6/J6 -> #DIV/0! | L6: =0.5*(K6^2-2)/(K6^2-1) -> #DIV/0!
A7: 0.1 | B7: =B6+50 -> 448 | C7: =Computations!AQ503 -> 0 | D7: =Computations!AQ444 -> #DIV/0! | E7: =Computations!BJ385+Figures!BJ389 -> 0 | F7: =Computations!BJ562 -> 0 | G7: =Computations!BJ680 -> 0 | H7: =Computations!AQ739 -> 0 | I7: =Computations!BJ798 -> 0 | J7: =Computations!BJ857 -> 0 | K7: =I7/J7 -> #DIV/0! | L7: =0.5*(K7^2-2)/(K7^2-1) -> #DIV/0!
A8: 0.1 | B8: =B7+50 -> 498 | C8: =Computations!AQ504 -> 0 | D8: =Computations!AQ445 -> #DIV/0! | E8: =Computations!BJ386+Figures!BJ390 -> 0 | F8: =Computations!BJ563 -> 0 | G8: =Computations!BJ681 -> 0 | H8: =Computations!AQ740 -> 0 | I8: =Computations!BJ799 -> 0 | J8: =Computations!BJ858 -> 0 | K8: =I8/J8 -> #DIV/0! | L8: =0.5*(K8^2-2)/(K8^2-1) -> #DIV/0!
A9: 0.1 | B9: =B8+50 -> 548 | C9: =Computations!AQ505 -> 0 | D9: =Computations!AQ446 -> #DIV/0! | E9: =Computations!BJ387+Figures!BJ391 -> 0 | F9: =Computations!BJ564 -> 0 | G9: =Computations!BJ682 -> 0 | H9: =Computations!AQ741 -> 0 | I9: =Computations!BJ800 -> 0 | J9: =Computations!BJ859 -> 0 | K9: =I9/J9 -> #DIV/0! | L9: =0.5*(K9^2-2)/(K9^2-1) -> #DIV/0!
A10: 0.1 | B10: =B9+50 -> 598 | C10: =Computations!AQ506 -> 0 | D10: =Computations!AQ447 -> #DIV/0! | E10: =Computations!BJ388+Figures!BJ392 -> 0 | F10: =Computations!BJ565 -> 0 | G10: =Computations!BJ683 -> 0 | H10: =Computations!AQ742 -> 0 | I10: =Computations!BJ801 -> 0 | J10: =Computations!BJ860 -> 0 | K10: =I10/J10 -> #DIV/0! | L10: =0.5*(K10^2-2)/(K10^2-1) -> #DIV/0!
A11: 0.1 | B11: =B10+50 -> 648 | C11: =Computations!AQ507 -> 0 | D11: =Computations!AQ448 -> #DIV/0! | E11: =Computations!BJ389+Figures!BJ393 -> 0 | F11: =Computations!BJ566 -> 0 | G11: =Computations!BJ684 -> 0 | H11: =Computations!AQ743 -> 0 | I11: =Computations!BJ802 -> 0 | J11: =Computations!BJ861 -> 0 | K11: =I11/J11 -> #DIV/0! | L11: =0.5*(K11^2-2)/(K11^2-1) -> #DIV/0!
A12: 0.1 | B12: =B11+50 -> 698 | C12: =Computations!AQ508 -> 0 | D12: =Computations!AQ449 -> #DIV/0! | E12: =Computations!BJ390+Figures!BJ394 -> 0 | F12: =Computations!BJ567 -> 0 | G12: =Computations!BJ685 -> 0 | H12: =Computations!AQ744 -> 0 | I12: =Computations!BJ803 -> 0 | J12: =Computations!BJ862 -> 0 | K12: =I12/J12 -> #DIV/0! | L12: =0.5*(K12^2-2)/(K12^2-1) -> #DIV/0!
A13: 0.1 | B13: =B12+50 -> 748 | C13: =Computations!AQ509 -> 0 | D13: =Computations!AQ450 -> #DIV/0! | E13: =Computations!BJ391+Figures!BJ395 -> 0 | F13: =Computations!BJ568 -> 0 | G13: =Computations!BJ686 -> 0 | H13: =Computations!AQ745 -> 0 | I13: =Computations!BJ804 -> 0 | J13: =Computations!BJ863 -> 0 | K13: =I13/J13 -> #DIV/0! | L13: =0.5*(K13^2-2)/(K13^2-1) -> #DIV/0!
A14: 0.1 | B14: =B13+50 -> 798 | C14: =Computations!AQ510 -> 0 | D14: =Computations!AQ451 -> #DIV/0! | E14: =Computations!BJ392+Figures!BJ396 -> 0 | F14: =Computations!BJ569 -> 0 | G14: =Computations!BJ687 -> 0 | H14: =Computations!AQ746 -> 0 | I14: =Computations!BJ805 -> 0 | J14: =Computations!BJ864 -> 0 | K14: =I14/J14 -> #DIV/0! | L14: =0.5*(K14^2-2)/(K14^2-1) -> #DIV/0!
A15: 0.1 | B15: =B14+50 -> 848 | C15: =Computations!AQ511 -> 0 | D15: =Computations!AQ452 -> #DIV/0! | E15: =Computations!BJ393+Figures!BJ397 -> 0 | F15: =Computations!BJ570 -> 0 | G15: =Computations!BJ688 -> 0 | H15: =Computations!AQ747 -> 0 | I15: =Computations!BJ806 -> 0 | J15: =Computations!BJ865 -> 0 | K15: =I15/J15 -> #DIV/0! | L15: =0.5*(K15^2-2)/(K15^2-1) -> #DIV/0!
A16: 0.1 | B16: =B15+50 -> 898 | C16: =Computations!AQ512 -> 0 | D16: =Computations!AQ453 -> #DIV/0! | E16: =Computations!BJ394+Figures!BJ398 -> 0 | F16: =Computations!BJ571 -> 0 | G16: =Computations!BJ689 -> 0 | H16: =Computations!AQ748 -> 0 | I16: =Computations!BJ807 -> 0 | J16: =Computations!BJ866 -> 0 | K16: =I16/J16 -> #DIV/0! | L16: =0.5*(K16^2-2)/(K16^2-1) -> #DIV/0!
A17: 0.1 | B17: =B16+50 -> 948 | C17: =Computations!AQ513 -> 0 | D17: =Computations!AQ454 -> #DIV/0! | E17: =Computations!BJ395+Figures!BJ399 -> 0 | F17: =Computations!BJ572 -> 0 | G17: =Computations!BJ690 -> 0 | H17: =Computations!AQ749 -> 0 | I17: =Computations!BJ808 -> 0 | J17: =Computations!BJ867 -> 0 | K17: =I17/J17 -> #DIV/0! | L17: =0.5*(K17^2-2)/(K17^2-1) -> #DIV/0!
A18: 570.1 | B18: 298 | C18: =Computations!AQ514 -> 0 | D18: =Computations!AQ455 -> #DIV/0! | E18: =Computations!BJ396+Figures!BJ400 -> 0 | F18: =Computations!BJ573 -> 0 | G18: =Computations!BJ691 -> 0 | H18: =Computations!AQ750 -> 0 | I18: =Computations!BJ809 -> 0 | J18: =Computations!BJ868 -> 0 | K18: =I18/J18 -> #DIV/0! | L18: =0.5*(K18^2-2)/(K18^2-1) -> #DIV/0!
A19: 570.1 | B19: =B18+50 -> 348 | C19: =Computations!AQ515 -> 0 | D19: =Computations!AQ456 -> #DIV/0! | E19: =Computations!BJ397+Figures!BJ401 -> 0 | F19: =Computations!BJ574 -> 0 | G19: =Computations!BJ692 -> 0 | H19: =Computations!AQ751 -> 0 | I19: =Computations!BJ810 -> 0 | J19: =Computations!BJ869 -> 0 | K19: =I19/J19 -> #DIV/0! | L19: =0.5*(K19^2-2)/(K19^2-1) -> #DIV/0!
A20: 570.1 | B20: =B19+50 -> 398 | C20: =Computations!AQ516 -> 0 | D20: =Computations!AQ457 -> #DIV/0! | E20: =Computations!BJ398+Figures!BJ402 -> 0 | F20: =Computations!BJ575 -> 0 | G20: =Computations!BJ693 -> 0 | H20: =Computations!AQ752 -> 0 | I20: =Computations!BJ811 -> 0 | J20: =Computations!BJ870 -> 0 | K20: =I20/J20 -> #DIV/0! | L20: =0.5*(K20^2-2)/(K20^2-1) -> #DIV/0!
A21: 570.1 | B21: =B20+50 -> 448 | C21: =Computations!AQ517 -> 0 | D21: =Computations!AQ458 -> #DIV/0! | E21: =Computations!BJ399+Figures!BJ403 -> 0 | F21: =Computations!BJ576 -> 0 | G21: =Computations!BJ694 -> 0 | H21: =Computations!AQ753 -> 0 | I21: =Computations!BJ812 -> 0 | J21: =Computations!BJ871 -> 0 | K21: =I21/J21 -> #DIV/0! | L21: =0.5*(K21^2-2)/(K21^2-1) -> #DIV/0!
A22: 570.1 | B22: =B21+50 -> 498 | C22: =Computations!AQ518 -> 0 | D22: =Computations!AQ459 -> #DIV/0! | E22: =Computations!BJ400+Figures!BJ404 -> 0 | F22: =Computations!BJ577 -> 0 | G22: =Computations!BJ695 -> 0 | H22: =Computations!AQ754 -> 0 | I22: =Computations!BJ813 -> 0 | J22: =Computations!BJ872 -> 0 | K22: =I22/J22 -> #DIV/0! | L22: =0.5*(K22^2-2)/(K22^2-1) -> #DIV/0!
A23: 570.1 | B23: =B22+50 -> 548 | C23: =Computations!AQ519 -> 0 | D23: =Computations!AQ460 -> #DIV/0! | E23: =Computations!BJ401+Figures!BJ405 -> 0 | F23: =Computations!BJ578 -> 0 | G23: =Computations!BJ696 -> 0 | H23: =Computations!AQ755 -> 0 | I23: =Computations!BJ814 -> 0 | J23: =Computations!BJ873 -> 0 | K23: =I23/J23 -> #DIV/0! | L23: =0.5*(K23^2-2)/(K23^2-1) -> #DIV/0!
A24: 570.1 | B24: =B23+50 -> 598 | C24: =Computations!AQ520 -> 0 | D24: =Computations!AQ461 -> #DIV/0! | E24: =Computations!BJ402+Figures!BJ406 -> 0 | F24: =Computations!BJ579 -> 0 | G24: =Computations!BJ697 -> 0 | H24: =Computations!AQ756 -> 0 | I24: =Computations!BJ815 -> 0 | J24: =Computations!BJ874 -> 0 | K24: =I24/J24 -> #DIV/0! | L24: =0.5*(K24^2-2)/(K24^2-1) -> #DIV/0!
A25: 570.1 | B25: =B24+50 -> 648 | C25: =Computations!AQ521 -> 0 | D25: =Computations!AQ462 -> #DIV/0! | E25: =Computations!BJ403+Figures!BJ407 -> 0 | F25: =Computations!BJ580 -> 0 | G25: =Computations!BJ698 -> 0 | H25: =Computations!AQ757 -> 0 | I25: =Computations!BJ816 -> 0 | J25: =Computations!BJ875 -> 0 | K25: =I25/J25 -> #DIV/0! | L25: =0.5*(K25^2-2)/(K25^2-1) -> #DIV/0!
A26: 570.1 | B26: =B25+50 -> 698 | C26: =Computations!AQ522 -> 0 | D26: =Computations!AQ463 -> #DIV/0! | E26: =Computations!BJ404+Figures!BJ408 -> 0 | F26: =Computations!BJ581 -> 0 | G26: =Computations!BJ699 -> 0 | H26: =Computations!AQ758 -> 0 | I26: =Computations!BJ817 -> 0 | J26: =Computations!BJ876 -> 0 | K26: =I26/J26 -> #DIV/0! | L26: =0.5*(K26^2-2)/(K26^2-1) -> #DIV/0!
A27: 570.1 | B27: =B26+50 -> 748 | C27: =Computations!AQ523 -> 0 | D27: =Computations!AQ464 -> #DIV/0! | E27: =Computations!BJ405+Figures!BJ409 -> 0 | F27: =Computations!BJ582 -> 0 | G27: =Computations!BJ700 -> 0 | H27: =Computations!AQ759 -> 0 | I27: =Computations!BJ818 -> 0 | J27: =Computations!BJ877 -> 0 | K27: =I27/J27 -> #DIV/0! | L27: =0.5*(K27^2-2)/(K27^2-1) -> #DIV/0!
A28: 570.1 | B28: =B27+50 -> 798 | C28: =Computations!AQ524 -> 0 | D28: =Computations!AQ465 -> #DIV/0! | E28: =Computations!BJ406+Figures!BJ410 -> 0 | F28: =Computations!BJ583 -> 0 | G28: =Computations!BJ701 -> 0 | H28: =Computations!AQ760 -> 0 | I28: =Computations!BJ819 -> 0 | J28: =Computations!BJ878 -> 0 | K28: =I28/J28 -> #DIV/0! | L28: =0.5*(K28^2-2)/(K28^2-1) -> #DIV/0!
A29: 570.1 | B29: =B28+50 -> 848 | C29: =Computations!AQ525 -> 0 | D29: =Computations!AQ466 -> #DIV/0! | E29: =Computations!BJ407+Figures!BJ411 -> 0 | F29: =Computations!BJ584 -> 0 | G29: =Computations!BJ702 -> 0 | H29: =Computations!AQ761 -> 0 | I29: =Computations!BJ820 -> 0 | J29: =Computations!BJ879 -> 0 | K29: =I29/J29 -> #DIV/0! | L29: =0.5*(K29^2-2)/(K29^2-1) -> #DIV/0!
A30: 570.1 | B30: =B29+50 -> 898 | C30: =Computations!AQ526 -> 0 | D30: =Computations!AQ467 -> #DIV/0! | E30: =Computations!BJ408+Figures!BJ412 -> 0 | F30: =Computations!BJ585 -> 0 | G30: =Computations!BJ703 -> 0 | H30: =Computations!AQ762 -> 0 | I30: =Computations!BJ821 -> 0 | J30: =Computations!BJ880 -> 0 | K30: =I30/J30 -> #DIV/0! | L30: =0.5*(K30^2-2)/(K30^2-1) -> #DIV/0!
A31: 570.1 | B31: =B30+50 -> 948 | C31: =Computations!AQ527 -> 0 | D31: =Computations!AQ468 -> #DIV/0! | E31: =Computations!BJ409+Figures!BJ413 -> 0 | F31: =Computations!BJ586 -> 0 | G31: =Computations!BJ704 -> 0 | H31: =Computations!AQ763 -> 0 | I31: =Computations!BJ822 -> 0 | J31: =Computations!BJ881 -> 0 | K31: =I31/J31 -> #DIV/0! | L31: =0.5*(K31^2-2)/(K31^2-1) -> #DIV/0!
A32: 1140.1 | B32: 298 | C32: =Computations!AQ528 -> 0 | D32: =Computations!AQ469 -> #DIV/0! | E32: =Computations!BJ410+Figures!BJ414 -> 0 | F32: =Computations!BJ587 -> 0 | G32: =Computations!BJ705 -> 0 | H32: =Computations!AQ764 -> 0 | I32: =Computations!BJ823 -> 0 | J32: =Computations!BJ882 -> 0 | K32: =I32/J32 -> #DIV/0! | L32: =0.5*(K32^2-2)/(K32^2-1) -> #DIV/0!
A33: 1140.1 | B33: =B32+50 -> 348 | C33: =Computations!AQ529 -> 0 | D33: =Computations!AQ470 -> #DIV/0! | E33: =Computations!BJ411+Figures!BJ415 -> 0 | F33: =Computations!BJ588 -> 0 | G33: =Computations!BJ706 -> 0 | H33: =Computations!AQ765 -> 0 | I33: =Computations!BJ824 -> 0 | J33: =Computations!BJ883 -> 0 | K33: =I33/J33 -> #DIV/0! | L33: =0.5*(K33^2-2)/(K33^2-1) -> #DIV/0!
A34: 1140.1 | B34: =B33+50 -> 398 | C34: =Computations!AQ530 -> 0 | D34: =Computations!AQ471 -> #DIV/0! | E34: =Computations!BJ412+Figures!BJ416 -> 0 | F34: =Computations!BJ589 -> 0 | G34: =Computations!BJ707 -> 0 | H34: =Computations!AQ766 -> 0 | I34: =Computations!BJ825 -> 0 | J34: =Computations!BJ884 -> 0 | K34: =I34/J34 -> #DIV/0! | L34: =0.5*(K34^2-2)/(K34^2-1) -> #DIV/0!
A35: 1140.1 | B35: =B34+50 -> 448 | C35: =Computations!AQ531 -> 0 | D35: =Computations!AQ472 -> #DIV/0! | E35: =Computations!BJ413+Figures!BJ417 -> 0 | F35: =Computations!BJ590 -> 0 | G35: =Computations!BJ708 -> 0 | H35: =Computations!AQ767 -> 0 | I35: =Computations!BJ826 -> 0 | J35: =Computations!BJ885 -> 0 | K35: =I35/J35 -> #DIV/0! | L35: =0.5*(K35^2-2)/(K35^2-1) -> #DIV/0!
A36: 1140.1 | B36: =B35+50 -> 498 | C36: =Computations!AQ532 -> 0 | D36: =Computations!AQ473 -> #DIV/0! | E36: =Computations!BJ414+Figures!BJ418 -> 0 | F36: =Computations!BJ591 -> 0 | G36: =Computations!BJ709 -> 0 | H36: =Computations!AQ768 -> 0 | I36: =Computations!BJ827 -> 0 | J36: =Computations!BJ886 -> 0 | K36: =I36/J36 -> #DIV/0! | L36: =0.5*(K36^2-2)/(K36^2-1) -> #DIV/0!
A37: 1140.1 | B37: =B36+50 -> 548 | C37: =Computations!AQ533 -> 0 | D37: =Computations!AQ474 -> #DIV/0! | E37: =Computations!BJ415+Figures!BJ419 -> 0 | F37: =Computations!BJ592 -> 0 | G37: =Computations!BJ710 -> 0 | H37: =Computations!AQ769 -> 0 | I37: =Computations!BJ828 -> 0 | J37: =Computations!BJ887 -> 0 | K37: =I37/J37 -> #DIV/0! | L37: =0.5*(K37^2-2)/(K37^2-1) -> #DIV/0!
A38: 1140.1 | B38: =B37+50 -> 598 | C38: =Computations!AQ534 -> 0 | D38: =Computations!AQ475 -> #DIV/0! | E38: =Computations!BJ416+Figures!BJ420 -> 0 | F38: =Computations!BJ593 -> 0 | G38: =Computations!BJ711 -> 0 | H38: =Computations!AQ770 -> 0 | I38: =Computations!BJ829 -> 0 | J38: =Computations!BJ888 -> 0 | K38: =I38/J38 -> #DIV/0! | L38: =0.5*(K38^2-2)/(K38^2-1) -> #DIV/0!
A39: 1140.1 | B39: =B38+50 -> 648 | C39: =Computations!AQ535 -> 0 | D39: =Computations!AQ476 -> #DIV/0! | E39: =Computations!BJ417+Figures!BJ421 -> 0 | F39: =Computations!BJ594 -> 0 | G39: =Computations!BJ712 -> 0 | H39: =Computations!AQ771 -> 0 | I39: =Computations!BJ830 -> 0 | J39: =Computations!BJ889 -> 0 | K39: =I39/J39 -> #DIV/0! | L39: =0.5*(K39^2-2)/(K39^2-1) -> #DIV/0!
A40: 1140.1 | B40: =B39+50 -> 698 | C40: =Computations!AQ536 -> 0 | D40: =Computations!AQ477 -> #DIV/0! | E40: =Computations!BJ418+Figures!BJ422 -> 0 | F40: =Computations!BJ595 -> 0 | G40: =Computations!BJ713 -> 0 | H40: =Computations!AQ772 -> 0 | I40: =Computations!BJ831 -> 0 | J40: =Computations!BJ890 -> 0 | K40: =I40/J40 -> #DIV/0! | L40: =0.5*(K40^2-2)/(K40^2-1) -> #DIV/0!
...

Sheet Significance
A1: Answer the following questions below with respect to the graphs that are produced for each rock type.
A2: Place an 'x' under the appropriate column based on whether the physical property increases or decreases with respect to the state variables listed below. Then add an 'x' to the significance column if the state variable creates a minimum of 10% change over the range of typical crustal temperatures and pressures. Some answers may be a little ambigous based on the results, if so, feel free to note these.
A3: 1. The effect of pressure on
C4: increase | D4: decrease | E4: significant (>10%)
A5: Expansivity
A6: Density
A7: Bulk Modulus
A8: Shear Modulus
A9: Specific Heat Capacity
A10: P-wave Velocity
A11: S-wave Velocity
A12: Vp/Vs Ratio
A13: Poisson Ratio
A15: 2. The effect of temperature on
C16: increase | D16: decrease | E16: significant (>10%)
A17: Expansivity
A18: Density
A19: Bulk Modulus
A20: Shear Modulus
A21: Specific Heat Capacity
A22: P-wave Velocity
A23: S-wave Velocity
A24: Vp/Vs Ratio
A25: Poisson Ratio
A27: 3. The effect of composition on (from felsic to mafic…decreasing SiO2)
C28: increase | D28: decrease | E28: significant (>10%)
A29: Expansivity
A30: Density
A31: Bulk Modulus
A32: Shear Modulus
A33: Specific Heat Capacity
A34: P-wave Velocity
A35: S-wave Velocity
A36: Vp/Vs Ratio
A37: Poisson Ratio
A39: 4. Rank the influence on the physical properties (1 to 3, most to least important)
C40: pressure | D40: temperature | E40: composition
A41: Expansivity
A42: Density
A43: Bulk Modulus
...
